Running as leaf node
<urlopen error timed out>
<urlopen error timed out>
<urlopen error timed out>
<urlopen error timed out>
<urlopen error timed out>
Traceback (most recent call last):
  File "/app/venv/lib/python3.9/site-packages/pyp2p/net.py", line 729, in start
    rendezvous_con = self.rendezvous.server_connect()
  File "/app/venv/lib/python3.9/site-packages/pyp2p/rendezvous_client.py", line 101, in server_connect
    raise Exception("All rendezvous servers are down.")
Exception: All rendezvous servers are down.

During handling of the above exception, another exception occurred:

Traceback (most recent call last):
  File "/app/secure_file_sender.py", line 140, in <module>
    node.start_node()
  File "/app/secure_file_sender.py", line 25, in start_node
    self.start()
  File "/app/venv/lib/python3.9/site-packages/pyp2p/net.py", line 732, in start
    raise Exception("Unable to connect to rendezvous server.")
Exception: Unable to connect to rendezvous server.
